<?xml version="1.0" ?>
<robot name="panda" xmlns:xacro="http://www.ros.org/wiki/xacro">
  <link name="panda_link_base">
    <inertial>
      <origin rpy="0 0 0" xyz="0 0 0.05"/>
       <mass value="2.9"/>
       <inertia ixx="0.1" ixy="0" ixz="0" iyy="0.1" iyz="0" izz="0.1"/>
    </inertial>
    <visual>
      <geometry>
        <mesh filename="franka_panda/meshes/collision/link0.obj"/>
      </geometry>
      <material name="panda_white">
    		<color rgba="1. 1. 1. 1."/>
  		</material>
    </visual>
    <collision>
      <geometry>
        <mesh filename="franka_panda/meshes/collision/link0.obj"/>
      </geometry>
      <material name="panda_white"/>
    </collision>
  </link>
  <link name="panda_link_0">
  	<inertial>
      <origin rpy="0 0 0" xyz="0 -0.04 -0.05"/>
       <mass value="2.7"/>
       <inertia ixx="0.1" ixy="0" ixz="0" iyy="0.1" iyz="0" izz="0.1"/>
    </inertial>
    <visual>
      <geometry>
        <mesh filename="franka_panda/meshes/visual/link1.obj"/>
      </geometry>
      <material name="panda_white"/>
    </visual>
    <collision>
      <geometry>
        <mesh filename="franka_panda/meshes/collision/link1.obj"/>
      </geometry>
      <material name="panda_white"/>
    </collision>
  </link>
  <joint name="panda_joint_0" type="revolute">
    <safety_controller k_position="100.0" k_velocity="40.0" soft_lower_limit="-2.8973" soft_upper_limit="2.8973"/>
    <origin rpy="0 0 0" xyz="0 0 0.333"/>
    <parent link="panda_link_base"/>
    <child link="panda_link_0"/>
    <axis xyz="0 0 1"/>
    <limit effort="87" lower="-2.9671" upper="2.9671" velocity="2.1750"/>
  </joint>
  <link name="panda_link_1">
  	<inertial>
      <origin rpy="0 0 0" xyz="0 -0.04 0.06"/>
       <mass value="2.73"/>
       <inertia ixx="0.1" ixy="0" ixz="0" iyy="0.1" iyz="0" izz="0.1"/>
    </inertial>
    <visual>
      <geometry>
        <mesh filename="franka_panda/meshes/visual/link2.obj"/>
      </geometry>
      <material name="panda_white"/>
    </visual>
    <collision>
      <geometry>
        <mesh filename="franka_panda/meshes/collision/link2.obj"/>
      </geometry>
      <material name="panda_white"/>
    </collision>
  </link>
  <joint name="panda_joint_1" type="revolute">
    <safety_controller k_position="100.0" k_velocity="40.0" soft_lower_limit="-1.7628" soft_upper_limit="1.7628"/>
    <origin rpy="-1.57079632679 0 0" xyz="0 0 0"/>
    <parent link="panda_link_0"/>
    <child link="panda_link_1"/>
    <axis xyz="0 0 1"/>
    <limit effort="87" lower="-1.8326" upper="1.8326" velocity="2.1750"/>
  </joint>
  <link name="panda_link_2">
	  <inertial>
      <origin rpy="0 0 0" xyz="0.01 0.01 -0.05"/>
       <mass value="2.04"/>
       <inertia ixx="0.1" ixy="0" ixz="0" iyy="0.1" iyz="0" izz="0.1"/>
    </inertial>
    <visual>
      <geometry>
        <mesh filename="franka_panda/meshes/visual/link3.obj"/>
      </geometry>
      <material name="panda_red">
    		<color rgba="1. 1. 1. 1."/>
  		</material>
    </visual>
    <collision>
      <geometry>
        <mesh filename="franka_panda/meshes/collision/link3.obj"/>
      </geometry>
    </collision>
  </link>
  <joint name="panda_joint_2" type="revolute">
    <safety_controller k_position="100.0" k_velocity="40.0" soft_lower_limit="-2.8973" soft_upper_limit="2.8973"/>
    <origin rpy="1.57079632679 0 0" xyz="0 -0.316 0"/>
    <parent link="panda_link_1"/>
    <child link="panda_link_2"/>
    <axis xyz="0 0 1"/>
    <limit effort="87" lower="-2.9671" upper="2.9671" velocity="2.1750"/>
  </joint>
  <link name="panda_link_3">
  	<inertial>
      <origin rpy="0 0 0" xyz="-0.03 0.03 0.02"/>
       <mass value="2.08"/>
       <inertia ixx="0.1" ixy="0" ixz="0" iyy="0.1" iyz="0" izz="0.1"/>
    </inertial>
    <visual>
      <geometry>
        <mesh filename="franka_panda/meshes/visual/link4.obj"/>
      </geometry>
      <material name="panda_white"/>
    </visual>
    <collision>
      <geometry>
        <mesh filename="franka_panda/meshes/collision/link4.obj"/>
      </geometry>
      <material name="panda_white"/>
    </collision>
  </link>
  <joint name="panda_joint_3" type="revolute">
    <safety_controller k_position="100.0" k_velocity="40.0" soft_lower_limit="-3.0718" soft_upper_limit="-0.0698"/>
    <origin rpy="1.57079632679 0 0" xyz="0.0825 0 0"/>
    <parent link="panda_link_2"/>
    <child link="panda_link_3"/>
    <axis xyz="0 0 1"/>
    <limit effort="87" lower="-3.1416" upper="0.0" velocity="2.1750"/>
  </joint>
  <link name="panda_link_4">
  	<inertial>
      <origin rpy="0 0 0" xyz="0 0.04 -0.12"/>
       <mass value="3"/>
       <inertia ixx="0.1" ixy="0" ixz="0" iyy="0.1" iyz="0" izz="0.1"/>
    </inertial>
    <visual>
      <geometry>
        <mesh filename="franka_panda/meshes/visual/link5.obj"/>
      </geometry>
      <material name="panda_white"/>
    </visual>
    <collision>
      <geometry>
        <mesh filename="franka_panda/meshes/collision/link5.obj"/>
      </geometry>
      <material name="panda_white"/>
    </collision>
  </link>
  <joint name="panda_joint_4" type="revolute">
    <safety_controller k_position="100.0" k_velocity="40.0" soft_lower_limit="-2.8973" soft_upper_limit="2.8973"/>
    <origin rpy="-1.57079632679 0 0" xyz="-0.0825 0.384 0"/>
    <parent link="panda_link_3"/>
    <child link="panda_link_4"/>
    <axis xyz="0 0 1"/>
    <limit effort="12" lower="-2.9671" upper="2.9671" velocity="2.6100"/>
  </joint>
  <link name="panda_link_5">
  	<inertial>
      <origin rpy="0 0 0" xyz="0.04 0 0"/>
       <mass value="1.3"/>
       <inertia ixx="0.1" ixy="0" ixz="0" iyy="0.1" iyz="0" izz="0.1"/>
    </inertial>
    <visual>
      <geometry>
        <mesh filename="franka_panda/meshes/visual/link6.obj"/>
      </geometry>
      <material name="panda_white"/>
    </visual>
    <collision>
      <geometry>
        <mesh filename="franka_panda/meshes/collision/link6.obj"/>
      </geometry>
      <material name="panda_white"/>
    </collision>
  </link>
  <joint name="panda_joint_5" type="revolute">
    <safety_controller k_position="100.0" k_velocity="40.0" soft_lower_limit="-0.0175" soft_upper_limit="3.7525"/>
    <origin rpy="1.57079632679 0 0" xyz="0 0 0"/>
    <parent link="panda_link_4"/>
    <child link="panda_link_5"/>
    <axis xyz="0 0 1"/>
    <limit effort="12" lower="-0.0873" upper="3.8223" velocity="2.6100"/>
  </joint>
  <link name="panda_link_6">
  	<inertial>
      <origin rpy="0 0 0" xyz="0 0 0.08"/>
       <mass value=".2"/>
       <inertia ixx="0.1" ixy="0" ixz="0" iyy="0.1" iyz="0" izz="0.1"/>
    </inertial>
    <visual>
      <geometry>
        <mesh filename="franka_panda/meshes/collision/link7.obj"/>
      </geometry>
      <material name="panda_white"/>
    </visual>
    <collision>
      <geometry>
        <mesh filename="franka_panda/meshes/collision/link7.obj"/>
      </geometry>
      <material name="panda_white"/>
    </collision>
  </link>
  <joint name="panda_joint_6" type="revolute">
    <safety_controller k_position="100.0" k_velocity="40.0" soft_lower_limit="-2.8973" soft_upper_limit="2.8973"/>
    <origin rpy="1.57079632679 0 0" xyz="0.088 0 0"/>
    <parent link="panda_link_5"/>
    <child link="panda_link_6"/>
    <axis xyz="0 0 1"/>
    <limit effort="12" lower="-2.9671" upper="2.9671" velocity="2.6100"/>
  </joint>

  <link name="peg_link">
<!--     <contact>
      <stiffness value="300000.0"/>
      <damping value="100.0"/>
      <lateral_friction value="0"/>
      <spinning_friction value="0"/>
      <rolling_friction value="0"/>
    </contact> -->
    <inertial>
      <origin rpy="0 0 0" xyz="0 0 0"/>
       <mass value=".2"/>
       <inertia ixx="0.1" ixy="0" ixz="0" iyy="0.1" iyz="0" izz="0.1"/>
    </inertial>
    <visual>
      <geometry>
        <!-- <cylinder length="0.001" radius="0.001"/> -->
        <mesh filename="peg.obj" scale="1 1 1"/>
      </geometry>
      <material name="panda_white"/>
    </visual>
    <collision>
      <geometry>
        <!-- <cylinder length="0.001" radius="0.001"/> -->
        <mesh filename="peg.obj" scale="1 1 1"/>
      </geometry>
      <material name="panda_white"/>
    </collision>
  </link>

  <joint name="panda_peg_joint" type="fixed">
    <!-- <origin rpy="0 0 -0.785398" xyz="0 0 0.105"/> -->
    <origin rpy="0 0 2.35619432679" xyz="0 0 0.105"/>
    <parent link="panda_link_6"/>
    <child link="peg_link"/>
    <axis xyz="0 0 0"/>
  </joint>

  <link name="camera_eye_link">
  <inertial>
      <origin rpy="0 0 0" xyz="0 0 0"/>
       <mass value="0.0"/>
       <inertia ixx="0.1" ixy="0" ixz="0" iyy="0.1" iyz="0" izz="0.1"/>
    </inertial>
   </link>

 <joint name="peg_camera_joint" type="fixed">
    <parent link="peg_link"/>
    <child link="camera_eye_link"/>
    <origin rpy="3.4382986 0 0" xyz="-0.032465 0.11689 -0.018024"/>
 </joint>

  <link name="end_effector_link">
  <inertial>
      <origin rpy="0 0 0" xyz="0 0 0"/>
       <mass value="0.0"/>
       <inertia ixx="0.1" ixy="0" ixz="0" iyy="0.1" iyz="0" izz="0.1"/>
    </inertial>
   </link>

 <joint name="peg_end_effector_joint" type="fixed">
    <parent link="peg_link"/>
    <child link="end_effector_link"/>
    <origin rpy="0 0 0" xyz="0 0 0.066"/>
 </joint>

</robot>
